[2023-11-12T05:32:04.315+0000] {processor.py:157} INFO - Started process (PID=6518) to work on /opt/airflow/dags/clean_data.py
[2023-11-12T05:32:04.317+0000] {processor.py:829} INFO - Processing file /opt/airflow/dags/clean_data.py for tasks to queue
[2023-11-12T05:32:04.320+0000] {logging_mixin.py:151} INFO - [2023-11-12T05:32:04.320+0000] {dagbag.py:539} INFO - Filling up the DagBag from /opt/airflow/dags/clean_data.py
[2023-11-12T05:32:04.882+0000] {logging_mixin.py:151} INFO - starting cleaning
[2023-11-12T05:32:04.907+0000] {logging_mixin.py:151} INFO - [2023-11-12T05:32:04.899+0000] {dagbag.py:347} ERROR - Failed to import: /opt/airflow/dags/clean_data.py
Traceback (most recent call last):
  File "/home/airflow/.local/lib/python3.8/site-packages/airflow/models/dagbag.py", line 343, in parse
    loader.exec_module(new_module)
  File "<frozen importlib._bootstrap_external>", line 843, in exec_module
  File "<frozen importlib._bootstrap>", line 219, in _call_with_frames_removed
  File "/opt/airflow/dags/clean_data.py", line 55, in <module>
    clean()
  File "/opt/airflow/dags/clean_data.py", line 7, in clean
    df = pd.read_csv("/dags/data/scraped_data.csv")
  File "/home/airflow/.local/lib/python3.8/site-packages/pandas/util/_decorators.py", line 311, in wrapper
    return func(*args, **kwargs)
  File "/home/airflow/.local/lib/python3.8/site-packages/pandas/io/parsers/readers.py", line 586, in read_csv
    return _read(filepath_or_buffer, kwds)
  File "/home/airflow/.local/lib/python3.8/site-packages/pandas/io/parsers/readers.py", line 482, in _read
    parser = TextFileReader(filepath_or_buffer, **kwds)
  File "/home/airflow/.local/lib/python3.8/site-packages/pandas/io/parsers/readers.py", line 811, in __init__
    self._engine = self._make_engine(self.engine)
  File "/home/airflow/.local/lib/python3.8/site-packages/pandas/io/parsers/readers.py", line 1040, in _make_engine
    return mapping[engine](self.f, **self.options)  # type: ignore[call-arg]
  File "/home/airflow/.local/lib/python3.8/site-packages/pandas/io/parsers/c_parser_wrapper.py", line 51, in __init__
    self._open_handles(src, kwds)
  File "/home/airflow/.local/lib/python3.8/site-packages/pandas/io/parsers/base_parser.py", line 222, in _open_handles
    self.handles = get_handle(
  File "/home/airflow/.local/lib/python3.8/site-packages/pandas/io/common.py", line 702, in get_handle
    handle = open(
FileNotFoundError: [Errno 2] No such file or directory: '/dags/data/scraped_data.csv'
[2023-11-12T05:32:04.908+0000] {processor.py:841} WARNING - No viable dags retrieved from /opt/airflow/dags/clean_data.py
[2023-11-12T05:32:05.101+0000] {processor.py:179} INFO - Processing /opt/airflow/dags/clean_data.py took 0.789 seconds
[2023-11-12T05:32:38.148+0000] {processor.py:157} INFO - Started process (PID=6542) to work on /opt/airflow/dags/clean_data.py
[2023-11-12T05:32:38.150+0000] {processor.py:829} INFO - Processing file /opt/airflow/dags/clean_data.py for tasks to queue
[2023-11-12T05:32:38.154+0000] {logging_mixin.py:151} INFO - [2023-11-12T05:32:38.153+0000] {dagbag.py:539} INFO - Filling up the DagBag from /opt/airflow/dags/clean_data.py
[2023-11-12T05:32:38.707+0000] {logging_mixin.py:151} INFO - starting cleaning
[2023-11-12T05:32:38.727+0000] {logging_mixin.py:151} INFO - [2023-11-12T05:32:38.711+0000] {dagbag.py:347} ERROR - Failed to import: /opt/airflow/dags/clean_data.py
Traceback (most recent call last):
  File "/home/airflow/.local/lib/python3.8/site-packages/airflow/models/dagbag.py", line 343, in parse
    loader.exec_module(new_module)
  File "<frozen importlib._bootstrap_external>", line 843, in exec_module
  File "<frozen importlib._bootstrap>", line 219, in _call_with_frames_removed
  File "/opt/airflow/dags/clean_data.py", line 55, in <module>
    clean()
  File "/opt/airflow/dags/clean_data.py", line 7, in clean
    df = pd.read_csv("/dags/data/scraped_data.csv")
  File "/home/airflow/.local/lib/python3.8/site-packages/pandas/util/_decorators.py", line 311, in wrapper
    return func(*args, **kwargs)
  File "/home/airflow/.local/lib/python3.8/site-packages/pandas/io/parsers/readers.py", line 586, in read_csv
    return _read(filepath_or_buffer, kwds)
  File "/home/airflow/.local/lib/python3.8/site-packages/pandas/io/parsers/readers.py", line 482, in _read
    parser = TextFileReader(filepath_or_buffer, **kwds)
  File "/home/airflow/.local/lib/python3.8/site-packages/pandas/io/parsers/readers.py", line 811, in __init__
    self._engine = self._make_engine(self.engine)
  File "/home/airflow/.local/lib/python3.8/site-packages/pandas/io/parsers/readers.py", line 1040, in _make_engine
    return mapping[engine](self.f, **self.options)  # type: ignore[call-arg]
  File "/home/airflow/.local/lib/python3.8/site-packages/pandas/io/parsers/c_parser_wrapper.py", line 51, in __init__
    self._open_handles(src, kwds)
  File "/home/airflow/.local/lib/python3.8/site-packages/pandas/io/parsers/base_parser.py", line 222, in _open_handles
    self.handles = get_handle(
  File "/home/airflow/.local/lib/python3.8/site-packages/pandas/io/common.py", line 702, in get_handle
    handle = open(
FileNotFoundError: [Errno 2] No such file or directory: '/dags/data/scraped_data.csv'
[2023-11-12T05:32:38.729+0000] {processor.py:841} WARNING - No viable dags retrieved from /opt/airflow/dags/clean_data.py
[2023-11-12T05:32:38.931+0000] {processor.py:179} INFO - Processing /opt/airflow/dags/clean_data.py took 0.788 seconds
[2023-11-12T05:33:13.415+0000] {processor.py:157} INFO - Started process (PID=6579) to work on /opt/airflow/dags/clean_data.py
[2023-11-12T05:33:13.417+0000] {processor.py:829} INFO - Processing file /opt/airflow/dags/clean_data.py for tasks to queue
[2023-11-12T05:33:13.420+0000] {logging_mixin.py:151} INFO - [2023-11-12T05:33:13.420+0000] {dagbag.py:539} INFO - Filling up the DagBag from /opt/airflow/dags/clean_data.py
[2023-11-12T05:33:13.905+0000] {logging_mixin.py:151} INFO - starting cleaning
[2023-11-12T05:33:13.923+0000] {logging_mixin.py:151} INFO - [2023-11-12T05:33:13.908+0000] {dagbag.py:347} ERROR - Failed to import: /opt/airflow/dags/clean_data.py
Traceback (most recent call last):
  File "/home/airflow/.local/lib/python3.8/site-packages/airflow/models/dagbag.py", line 343, in parse
    loader.exec_module(new_module)
  File "<frozen importlib._bootstrap_external>", line 843, in exec_module
  File "<frozen importlib._bootstrap>", line 219, in _call_with_frames_removed
  File "/opt/airflow/dags/clean_data.py", line 55, in <module>
    clean()
  File "/opt/airflow/dags/clean_data.py", line 7, in clean
    df = pd.read_csv("/dags/data/scraped_data.csv")
  File "/home/airflow/.local/lib/python3.8/site-packages/pandas/util/_decorators.py", line 311, in wrapper
    return func(*args, **kwargs)
  File "/home/airflow/.local/lib/python3.8/site-packages/pandas/io/parsers/readers.py", line 586, in read_csv
    return _read(filepath_or_buffer, kwds)
  File "/home/airflow/.local/lib/python3.8/site-packages/pandas/io/parsers/readers.py", line 482, in _read
    parser = TextFileReader(filepath_or_buffer, **kwds)
  File "/home/airflow/.local/lib/python3.8/site-packages/pandas/io/parsers/readers.py", line 811, in __init__
    self._engine = self._make_engine(self.engine)
  File "/home/airflow/.local/lib/python3.8/site-packages/pandas/io/parsers/readers.py", line 1040, in _make_engine
    return mapping[engine](self.f, **self.options)  # type: ignore[call-arg]
  File "/home/airflow/.local/lib/python3.8/site-packages/pandas/io/parsers/c_parser_wrapper.py", line 51, in __init__
    self._open_handles(src, kwds)
  File "/home/airflow/.local/lib/python3.8/site-packages/pandas/io/parsers/base_parser.py", line 222, in _open_handles
    self.handles = get_handle(
  File "/home/airflow/.local/lib/python3.8/site-packages/pandas/io/common.py", line 702, in get_handle
    handle = open(
FileNotFoundError: [Errno 2] No such file or directory: '/dags/data/scraped_data.csv'
[2023-11-12T05:33:13.926+0000] {processor.py:841} WARNING - No viable dags retrieved from /opt/airflow/dags/clean_data.py
[2023-11-12T05:33:14.109+0000] {processor.py:179} INFO - Processing /opt/airflow/dags/clean_data.py took 0.697 seconds
