[2023-11-12T05:32:03.003+0000] {processor.py:157} INFO - Started process (PID=6513) to work on /opt/airflow/dags/prediction.py
[2023-11-12T05:32:03.005+0000] {processor.py:829} INFO - Processing file /opt/airflow/dags/prediction.py for tasks to queue
[2023-11-12T05:32:03.009+0000] {logging_mixin.py:151} INFO - [2023-11-12T05:32:03.008+0000] {dagbag.py:539} INFO - Filling up the DagBag from /opt/airflow/dags/prediction.py
[2023-11-12T05:32:03.976+0000] {logging_mixin.py:151} INFO - [2023-11-12T05:32:03.957+0000] {dagbag.py:347} ERROR - Failed to import: /opt/airflow/dags/prediction.py
Traceback (most recent call last):
  File "/home/airflow/.local/lib/python3.8/site-packages/airflow/models/dagbag.py", line 343, in parse
    loader.exec_module(new_module)
  File "<frozen importlib._bootstrap_external>", line 843, in exec_module
  File "<frozen importlib._bootstrap>", line 219, in _call_with_frames_removed
  File "/opt/airflow/dags/prediction.py", line 2, in <module>
    import tkinter as tk
  File "/usr/local/lib/python3.8/tkinter/__init__.py", line 36, in <module>
    import _tkinter # If this fails your Python may not be configured for Tk
ImportError: libtk8.6.so: cannot open shared object file: No such file or directory
[2023-11-12T05:32:04.047+0000] {processor.py:841} WARNING - No viable dags retrieved from /opt/airflow/dags/prediction.py
[2023-11-12T05:32:04.234+0000] {processor.py:179} INFO - Processing /opt/airflow/dags/prediction.py took 1.236 seconds
[2023-11-12T05:32:37.114+0000] {processor.py:157} INFO - Started process (PID=6538) to work on /opt/airflow/dags/prediction.py
[2023-11-12T05:32:37.116+0000] {processor.py:829} INFO - Processing file /opt/airflow/dags/prediction.py for tasks to queue
[2023-11-12T05:32:37.120+0000] {logging_mixin.py:151} INFO - [2023-11-12T05:32:37.119+0000] {dagbag.py:539} INFO - Filling up the DagBag from /opt/airflow/dags/prediction.py
[2023-11-12T05:32:37.929+0000] {logging_mixin.py:151} INFO - [2023-11-12T05:32:37.920+0000] {dagbag.py:347} ERROR - Failed to import: /opt/airflow/dags/prediction.py
Traceback (most recent call last):
  File "/home/airflow/.local/lib/python3.8/site-packages/airflow/models/dagbag.py", line 343, in parse
    loader.exec_module(new_module)
  File "<frozen importlib._bootstrap_external>", line 843, in exec_module
  File "<frozen importlib._bootstrap>", line 219, in _call_with_frames_removed
  File "/opt/airflow/dags/prediction.py", line 2, in <module>
    import tkinter as tk
  File "/usr/local/lib/python3.8/tkinter/__init__.py", line 36, in <module>
    import _tkinter # If this fails your Python may not be configured for Tk
ImportError: libtk8.6.so: cannot open shared object file: No such file or directory
[2023-11-12T05:32:37.933+0000] {processor.py:841} WARNING - No viable dags retrieved from /opt/airflow/dags/prediction.py
[2023-11-12T05:32:38.054+0000] {processor.py:179} INFO - Processing /opt/airflow/dags/prediction.py took 0.945 seconds
[2023-11-12T05:33:11.264+0000] {processor.py:157} INFO - Started process (PID=6562) to work on /opt/airflow/dags/prediction.py
[2023-11-12T05:33:11.266+0000] {processor.py:829} INFO - Processing file /opt/airflow/dags/prediction.py for tasks to queue
[2023-11-12T05:33:11.273+0000] {logging_mixin.py:151} INFO - [2023-11-12T05:33:11.272+0000] {dagbag.py:539} INFO - Filling up the DagBag from /opt/airflow/dags/prediction.py
[2023-11-12T05:33:12.202+0000] {logging_mixin.py:151} INFO - [2023-11-12T05:33:12.183+0000] {dagbag.py:347} ERROR - Failed to import: /opt/airflow/dags/prediction.py
Traceback (most recent call last):
  File "/home/airflow/.local/lib/python3.8/site-packages/airflow/models/dagbag.py", line 343, in parse
    loader.exec_module(new_module)
  File "<frozen importlib._bootstrap_external>", line 843, in exec_module
  File "<frozen importlib._bootstrap>", line 219, in _call_with_frames_removed
  File "/opt/airflow/dags/prediction.py", line 2, in <module>
    import tkinter as tk
  File "/usr/local/lib/python3.8/tkinter/__init__.py", line 36, in <module>
    import _tkinter # If this fails your Python may not be configured for Tk
ImportError: libtk8.6.so: cannot open shared object file: No such file or directory
[2023-11-12T05:33:12.206+0000] {processor.py:841} WARNING - No viable dags retrieved from /opt/airflow/dags/prediction.py
[2023-11-12T05:33:12.353+0000] {processor.py:179} INFO - Processing /opt/airflow/dags/prediction.py took 1.092 seconds
